<?xml version="1.0" encoding="utf-8"?>
<!-- This URDF was automatically created by SolidWorks to URDF Exporter! Originally created by Stephen Brawner (brawner@gmail.com) 
     Commit Version: 1.6.0-1-g15f4949  Build Version: 1.6.7594.29634
     For more information, please see http://wiki.ros.org/sw_urdf_exporter -->
<robot
  name="universal">
  <link
    name="base_link">
    <inertial>
      <origin
        xyz="-0.00414044238561839 -0.000691260188723397 0.0117699788251773"
        rpy="0 0 0" />
      <mass
        value="17.1531315996557" />
      <inertia
        ixx="0.0275273995724078"
        ixy="-8.22864842046397E-05"
        ixz="0.000931700623151425"
        iyy="0.0313450403332022"
        iyz="-5.19664788147283E-05"
        izz="0.0357084043722195" />
    </inertial>
    <visual>
      <origin
        xyz="0 0 0"
        rpy="0 0 0" />
      <geometry>
        <mesh
          filename="../meshes/base_link.STL" />
      </geometry>
      <material
        name="">
        <color
          rgba="0.752941176470588 0.752941176470588 0.752941176470588 1" />
      </material>
    </visual>
    <collision>
      <origin
        xyz="0 0 0"
        rpy="0 0 0" />
      <geometry>
        <mesh
          filename="../meshes/base_link.STL" />
      </geometry>
    </collision>
  </link>
  <link
    name="right_thigh">
    <inertial>
      <origin
        xyz="-0.11463603534979 0.00802052218660743 0.000250243368407732"
        rpy="0 0 0" />
      <mass
        value="0.441858933802641" />
      <inertia
        ixx="0.000184117233652697"
        ixy="-8.96093831711135E-06"
        ixz="3.62495659009169E-05"
        iyy="0.00317592791788235"
        iyz="2.62808479398655E-06"
        izz="0.00301801478319354" />
    </inertial>
    <visual>
      <origin
        xyz="0 0 0"
        rpy="0 0 0" />
      <geometry>
        <mesh
          filename="../meshes/right_thigh.STL" />
      </geometry>
      <material
        name="">
        <color
          rgba="0.792156862745098 0.819607843137255 0.933333333333333 1" />
      </material>
    </visual>
    <collision>
      <origin
        xyz="0 0 0"
        rpy="0 0 0" />
      <geometry>
        <mesh
          filename="../meshes/right_thigh.STL" />
      </geometry>
    </collision>
  </link>
  <joint
    name="right_hip"
    type="revolute">
    <origin
      xyz="0 -0.188999999999998 0"
      rpy="0 1.5707963267949 0" />
    <parent
      link="base_link" />
    <child
      link="right_thigh" />
    <axis
      xyz="0 1 0" />
    <limit
      effort="40"
      velocity="1000" />
  </joint>
  <link
    name="right_shank">
    <inertial>
      <origin
        xyz="0.198583417340179 -0.0182498340685918 0.00805495082504837"
        rpy="0 0 0" />
      <mass
        value="0.665022011740533" />
      <inertia
        ixx="0.000247019401526116"
        ixy="-4.50820506732406E-07"
        ixz="-0.000162685104870997"
        iyy="0.0063104229313752"
        iyz="-9.4711639318611E-07"
        izz="0.00609249840630011" />
    </inertial>
    <visual>
      <origin
        xyz="0 0 0"
        rpy="0 0 0" />
      <geometry>
        <mesh
          filename="../meshes/right_shank.STL" />
      </geometry>
      <material
        name="">
        <color
          rgba="1 1 1 1" />
      </material>
    </visual>
    <collision>
      <origin
        xyz="0 0 0"
        rpy="0 0 0" />
      <geometry>
        <mesh
          filename="../meshes/right_shank.STL" />
      </geometry>
    </collision>
  </link>
  <joint
    name="right_knee"
    type="revolute">
    <origin
      xyz="-0.25 0 0"
      rpy="0 0.47814 0" />
    <parent
      link="right_thigh" />
    <child
      link="right_shank" />
    <axis
      xyz="0 1 0" />
    <limit
      lower="0"
      upper="1.1414"
      effort="60"
      velocity="1000" />
  </joint>
  <link
    name="right_wheel">
    <inertial>
      <origin
        xyz="0 0.0144816532039134 -4.16333634234434E-17"
        rpy="0 0 0" />
      <mass
        value="0.204682671682961" />
      <inertia
        ixx="0.000239222338592518"
        ixy="-5.7884014169517E-19"
        ixz="-1.02743618190445E-19"
        iyy="0.000465851260808887"
        iyz="-5.38410926013559E-19"
        izz="0.000239222338592517" />
    </inertial>
    <visual>
      <origin
        xyz="0 0 0"
        rpy="0 0 0" />
      <geometry>
        <mesh
          filename="../meshes/right_wheel.STL" />
      </geometry>
      <material
        name="">
        <color
          rgba="0.898039215686275 0.917647058823529 0.929411764705882 1" />
      </material>
    </visual>
    <collision>
      <origin
        xyz="0 0.0125 0"
        rpy="1.5708 0 0" />
      <geometry>
        <cylinder length="0.025" radius="0.06" />
      </geometry>
    </collision>
  </link>
  <joint
    name="right_wheel_axis"
    type="revolute">
    <origin
      xyz="0.299776743957763 -0.0530500000000112 0.0115716801755387"
      rpy="3.14159265358979 -1.09265450367459 3.14159265358979" />
    <parent
      link="right_shank" />
    <child
      link="right_wheel" />
    <axis
      xyz="0 1 0" />
    <limit
      effort="3.8"
      velocity="1000" />
  </joint>
  <link
    name="left_thigh">
    <inertial>
      <origin
        xyz="-0.114636035349793 -0.0103849778759935 0.00025024336840751"
        rpy="0 0 0" />
      <mass
        value="0.44185893380264" />
      <inertia
        ixx="0.000184117233652697"
        ixy="1.93174051017026E-06"
        ixz="3.62495659009195E-05"
        iyy="0.00317592791788236"
        iyz="-4.71482613996317E-07"
        izz="0.00301801478319355" />
    </inertial>
    <visual>
      <origin
        xyz="0 0 0"
        rpy="0 0 0" />
      <geometry>
        <mesh
          filename="../meshes/left_thigh.STL" />
      </geometry>
      <material
        name="">
        <color
          rgba="0.792156862745098 0.819607843137255 0.933333333333333 1" />
      </material>
    </visual>
    <collision>
      <origin
        xyz="0 0 0"
        rpy="0 0 0" />
      <geometry>
        <mesh
          filename="../meshes/left_thigh.STL" />
      </geometry>
    </collision>
  </link>
  <joint
    name="left_hip"
    type="revolute">
    <origin
      xyz="0 0.189000000000002 0"
      rpy="0 1.5707963267949 0" />
    <parent
      link="base_link" />
    <child
      link="left_thigh" />
    <axis
      xyz="0 1 0" />
    <limit
      effort="40"
      velocity="1000" />
  </joint>
  <link
    name="left_shank">
    <inertial>
      <origin
        xyz="0.198589227412355 0.0182498337675623 0.00779435910757187"
        rpy="0 0 0" />
      <mass
        value="0.665022006366515" />
      <inertia
        ixx="0.000247115408819347"
        ixy="4.91331212099465E-07"
        ixz="-0.000164836780219266"
        iyy="0.00631042293136743"
        iyz="-8.69605071617117E-07"
        izz="0.00609240239899857" />
    </inertial>
    <visual>
      <origin
        xyz="0 0 0"
        rpy="0 0 0" />
      <geometry>
        <mesh
          filename="../meshes/left_shank.STL" />
      </geometry>
      <material
        name="">
        <color
          rgba="1 1 1 1" />
      </material>
    </visual>
    <collision>
      <origin
        xyz="0 0 0"
        rpy="0 0 0" />
      <geometry>
        <mesh
          filename="../meshes/left_shank.STL" />
      </geometry>
    </collision>
  </link>
  <joint
    name="left_knee"
    type="revolute">
    <origin
      xyz="-0.250000000000001 0 0"
      rpy="0 0.478141823120307 0" />
    <parent
      link="left_thigh" />
    <child
      link="left_shank" />
    <axis
      xyz="0 1 0" />
    <limit
      lower="0"
      upper="1.1414"
      effort="60"
      velocity="1000" />
  </joint>
  <link
    name="left_wheel">
    <inertial>
      <origin
        xyz="1.11022302462516E-16 -0.0144816532039134 3.46944695195361E-17"
        rpy="0 0 0" />
      <mass
        value="0.204682671682962" />
      <inertia
        ixx="0.000239222338592518"
        ixy="-1.44792859496127E-18"
        ixz="-1.60370745960042E-19"
        iyy="0.000465851260808888"
        iyz="-2.72311800680959E-19"
        izz="0.000239222338592518" />
    </inertial>
    <visual>
      <origin
        xyz="0 0 0"
        rpy="0 0 0" />
      <geometry>
        <mesh
          filename="../meshes/left_wheel.STL" />
      </geometry>
      <material
        name="">
        <color
          rgba="0.898039215686275 0.917647058823529 0.929411764705882 1" />
      </material>
    </visual>
    <collision>
      <origin
        xyz="0 -0.0125 0"
        rpy="1.5708 0 0" />
      <geometry>
        <cylinder length="0.025" radius="0.06" />
      </geometry>
    </collision>
  </link>
  <joint
    name="left_wheel_axis"
    type="revolute">
    <origin
      xyz="0.299776743957766 0.0530499999999951 0.0115716801755382"
      rpy="3.14159265358979 -1.09265450367459 3.14159265358979" />
    <parent
      link="left_shank" />
    <child
      link="left_wheel" />
    <axis
      xyz="0 1 0" />
    <limit
      effort="3.8"
      velocity="1000" />
  </joint>
</robot>